2025-06-02 17:45:59,232 - dme_collector - INFO - Fichier de sortie initialisé: /app/data/dme_data.csv
2025-06-02 17:45:59,233 - dme_collector - INFO - Démarrage de la collecte de données DME (intervalle: 180s)
2025-06-02 17:45:59,239 - urllib3.connectionpool - WARNING - Retrying (Retry(total=2, connect=None, read=None, redirect=None, status=None)) after connection broken by 'NewConnectionError('<urllib3.connection.HTTPConnection object at 0x7e763ce78550>: Failed to establish a new connection: [Errno 111] Connection refused')': /all
2025-06-02 17:46:01,242 - urllib3.connectionpool - WARNING - Retrying (Retry(total=1, connect=None, read=None, redirect=None, status=None)) after connection broken by 'NewConnectionError('<urllib3.connection.HTTPConnection object at 0x7e763ce787c0>: Failed to establish a new connection: [Errno 111] Connection refused')': /all
2025-06-02 17:46:05,248 - urllib3.connectionpool - WARNING - Retrying (Retry(total=0, connect=None, read=None, redirect=None, status=None)) after connection broken by 'NewConnectionError('<urllib3.connection.HTTPConnection object at 0x7e763ce789d0>: Failed to establish a new connection: [Errno 111] Connection refused')': /all
2025-06-02 17:46:05,256 - dme_collector - ERROR - Erreur de connexion au simulateur DME: HTTPConnectionPool(host='localhost', port=5000): Max retries exceeded with url: /all (Caused by NewConnectionError('<urllib3.connection.HTTPConnection object at 0x7e763ce78be0>: Failed to establish a new connection: [Errno 111] Connection refused'))
2025-06-02 17:48:50,572 - urllib3.connectionpool - WARNING - Retrying (Retry(total=2, connect=None, read=None, redirect=None, status=None)) after connection broken by 'NewConnectionError('<urllib3.connection.HTTPConnection object at 0x7e763ce78f10>: Failed to establish a new connection: [Errno 111] Connection refused')': /all
2025-06-02 17:48:52,599 - urllib3.connectionpool - WARNING - Retrying (Retry(total=1, connect=None, read=None, redirect=None, status=None)) after connection broken by 'NewConnectionError('<urllib3.connection.HTTPConnection object at 0x7e763ce201c0>: Failed to establish a new connection: [Errno 111] Connection refused')': /all
2025-06-02 17:48:56,759 - urllib3.connectionpool - WARNING - Retrying (Retry(total=0, connect=None, read=None, redirect=None, status=None)) after connection broken by 'NewConnectionError('<urllib3.connection.HTTPConnection object at 0x7e763ce78670>: Failed to establish a new connection: [Errno 111] Connection refused')': /all
2025-06-02 17:48:56,760 - dme_collector - ERROR - Erreur de connexion au simulateur DME: HTTPConnectionPool(host='localhost', port=5000): Max retries exceeded with url: /all (Caused by NewConnectionError('<urllib3.connection.HTTPConnection object at 0x7e763ce78c70>: Failed to establish a new connection: [Errno 111] Connection refused'))
2025-06-02 17:51:41,363 - urllib3.connectionpool - WARNING - Retrying (Retry(total=2, connect=None, read=None, redirect=None, status=None)) after connection broken by 'NewConnectionError('<urllib3.connection.HTTPConnection object at 0x7e763ce78910>: Failed to establish a new connection: [Errno 111] Connection refused')': /all
2025-06-02 17:51:43,427 - urllib3.connectionpool - WARNING - Retrying (Retry(total=1, connect=None, read=None, redirect=None, status=None)) after connection broken by 'NewConnectionError('<urllib3.connection.HTTPConnection object at 0x7e763ce67c70>: Failed to establish a new connection: [Errno 111] Connection refused')': /all
2025-06-02 17:51:47,450 - urllib3.connectionpool - WARNING - Retrying (Retry(total=0, connect=None, read=None, redirect=None, status=None)) after connection broken by 'NewConnectionError('<urllib3.connection.HTTPConnection object at 0x7e763ce203a0>: Failed to establish a new connection: [Errno 111] Connection refused')': /all
2025-06-02 17:51:47,451 - dme_collector - ERROR - Erreur de connexion au simulateur DME: HTTPConnectionPool(host='localhost', port=5000): Max retries exceeded with url: /all (Caused by NewConnectionError('<urllib3.connection.HTTPConnection object at 0x7e763ce205e0>: Failed to establish a new connection: [Errno 111] Connection refused'))
2025-06-02 17:53:58,316 - dme_collector - INFO - Démarrage de la collecte de données DME (intervalle: 180s)
2025-06-02 17:53:58,325 - urllib3.connectionpool - WARNING - Retrying (Retry(total=2, connect=None, read=None, redirect=None, status=None)) after connection broken by 'NewConnectionError('<urllib3.connection.HTTPConnection object at 0x7a86e586f550>: Failed to establish a new connection: [Errno 111] Connection refused')': /all
2025-06-02 17:54:00,328 - urllib3.connectionpool - WARNING - Retrying (Retry(total=1, connect=None, read=None, redirect=None, status=None)) after connection broken by 'NewConnectionError('<urllib3.connection.HTTPConnection object at 0x7a86e586f7c0>: Failed to establish a new connection: [Errno 111] Connection refused')': /all
2025-06-02 17:54:04,398 - urllib3.connectionpool - WARNING - Retrying (Retry(total=0, connect=None, read=None, redirect=None, status=None)) after connection broken by 'NewConnectionError('<urllib3.connection.HTTPConnection object at 0x7a86e586f9d0>: Failed to establish a new connection: [Errno 111] Connection refused')': /all
2025-06-02 17:54:04,411 - dme_collector - ERROR - Erreur de connexion au simulateur DME: HTTPConnectionPool(host='localhost', port=5000): Max retries exceeded with url: /all (Caused by NewConnectionError('<urllib3.connection.HTTPConnection object at 0x7a86e586fbe0>: Failed to establish a new connection: [Errno 111] Connection refused'))
2025-06-02 17:56:48,599 - urllib3.connectionpool - WARNING - Retrying (Retry(total=2, connect=None, read=None, redirect=None, status=None)) after connection broken by 'NewConnectionError('<urllib3.connection.HTTPConnection object at 0x7a86e586ff10>: Failed to establish a new connection: [Errno 111] Connection refused')': /all
2025-06-02 17:56:50,603 - urllib3.connectionpool - WARNING - Retrying (Retry(total=1, connect=None, read=None, redirect=None, status=None)) after connection broken by 'NewConnectionError('<urllib3.connection.HTTPConnection object at 0x7a86e58171c0>: Failed to establish a new connection: [Errno 111] Connection refused')': /all
2025-06-02 17:56:54,609 - urllib3.connectionpool - WARNING - Retrying (Retry(total=0, connect=None, read=None, redirect=None, status=None)) after connection broken by 'NewConnectionError('<urllib3.connection.HTTPConnection object at 0x7a86e586f670>: Failed to establish a new connection: [Errno 111] Connection refused')': /all
2025-06-02 17:56:54,611 - dme_collector - ERROR - Erreur de connexion au simulateur DME: HTTPConnectionPool(host='localhost', port=5000): Max retries exceeded with url: /all (Caused by NewConnectionError('<urllib3.connection.HTTPConnection object at 0x7a86e586fc70>: Failed to establish a new connection: [Errno 111] Connection refused'))
